<?xml version="1.0" ?>
<!-- =================================================================================== -->
<!-- |    This document was autogenerated by xacro from /home/abcs/robo_ws/src/articubot_one/description/robot.urdf.xacro | -->
<!-- |    EDITING THIS FILE BY HAND IS NOT RECOMMENDED                                 | -->
<!-- =================================================================================== -->
<robot name="robot">
  <!-- Specify some standard inertial calculations https://en.wikipedia.org/wiki/List_of_moments_of_inertia -->
  <!-- These make use of xacro's mathematical functionality -->
  <!-- Materials -->
  <material name="white">
    <color rgba="1 1 1 1"/>
  </material>
  <material name="blue">
    <color rgba="0.2 0.2 1 1"/>
  </material>
  <material name="black">
    <color rgba="0 0 0 1"/>
  </material>
  <material name="red">
    <color rgba="1 0 0 1"/>
  </material>
  <!-- Base Link -->
  <link name="base_link"/>
  <!-- Chassis -->
  <joint name="chassis_joint" type="fixed">
    <parent link="base_link"/>
    <child link="chassis"/>
    <origin xyz="0 0 0"/>
  </joint>
  <link name="chassis"/>
  <joint name="top_pillar_fl_joint" type="fixed">
    <parent link="chassis"/>
    <child link="top_pillar_fl"/>
    <origin xyz="0.1175 0.1325 0.66"/>
  </joint>
  <link name="top_pillar_fl">
    <visual>
      <geometry>
        <box size="0.02 0.02 0.74"/>
      </geometry>
      <laser_retro>0.0</laser_retro>
      <material name="white"/>
    </visual>
    <collision>
      <geometry>
        <box size="0.02 0.02 0.74"/>
      </geometry>
    </collision>
    <inertial>
      <origin rpy="0 0 0" xyz="0 0 0"/>
      <mass value="0.3"/>
      <inertia ixx="0.013699999999999997" ixy="0.0" ixz="0.0" iyy="0.013699999999999997" iyz="0.0" izz="1.9999999999999998e-05"/>
    </inertial>
  </link>
  <joint name="top_pillar_fr_joint" type="fixed">
    <parent link="chassis"/>
    <child link="top_pillar_fr"/>
    <origin xyz="0.1175 -0.1325 0.66"/>
  </joint>
  <link name="top_pillar_fr">
    <visual>
      <geometry>
        <box size="0.02 0.02 0.74"/>
      </geometry>
      <laser_retro>0.0</laser_retro>
      <material name="white"/>
    </visual>
    <collision>
      <geometry>
        <box size="0.02 0.02 0.74"/>
      </geometry>
    </collision>
    <inertial>
      <origin rpy="0 0 0" xyz="0 0 0"/>
      <mass value="0.3"/>
      <inertia ixx="0.013699999999999997" ixy="0.0" ixz="0.0" iyy="0.013699999999999997" iyz="0.0" izz="1.9999999999999998e-05"/>
    </inertial>
  </link>
  <joint name="top_pillar_rl_joint" type="fixed">
    <parent link="chassis"/>
    <child link="top_pillar_rl"/>
    <origin xyz="-0.1175 0.1325 0.66"/>
  </joint>
  <link name="top_pillar_rl">
    <visual>
      <geometry>
        <box size="0.02 0.02 0.74"/>
      </geometry>
      <laser_retro>0.0</laser_retro>
      <material name="white"/>
    </visual>
    <collision>
      <geometry>
        <box size="0.02 0.02 0.74"/>
      </geometry>
    </collision>
    <inertial>
      <origin rpy="0 0 0" xyz="0 0 0"/>
      <mass value="0.3"/>
      <inertia ixx="0.013699999999999997" ixy="0.0" ixz="0.0" iyy="0.013699999999999997" iyz="0.0" izz="1.9999999999999998e-05"/>
    </inertial>
  </link>
  <joint name="top_pillar_rr_joint" type="fixed">
    <parent link="chassis"/>
    <child link="top_pillar_rr"/>
    <origin xyz="-0.1175 -0.1325 0.66"/>
  </joint>
  <link name="top_pillar_rr">
    <visual>
      <geometry>
        <box size="0.02 0.02 0.74"/>
      </geometry>
      <laser_retro>0.0</laser_retro>
      <material name="white"/>
    </visual>
    <collision>
      <geometry>
        <box size="0.02 0.02 0.74"/>
      </geometry>
    </collision>
    <inertial>
      <origin rpy="0 0 0" xyz="0 0 0"/>
      <mass value="0.3"/>
      <inertia ixx="0.013699999999999997" ixy="0.0" ixz="0.0" iyy="0.013699999999999997" iyz="0.0" izz="1.9999999999999998e-05"/>
    </inertial>
  </link>
  <joint name="pillar_fl_joint" type="fixed">
    <parent link="chassis"/>
    <child link="pillar_fl"/>
    <origin xyz="0.24 0.23 0.145"/>
  </joint>
  <link name="pillar_fl">
    <visual>
      <geometry>
        <box size="0.02 0.02 0.29"/>
      </geometry>
      <material name="black"/>
    </visual>
    <collision>
      <geometry>
        <box size="0.02 0.02 0.29"/>
      </geometry>
    </collision>
    <inertial>
      <origin rpy="0 0 0" xyz="0 0 0"/>
      <mass value="0.1"/>
      <inertia ixx="0.0007041666666666666" ixy="0.0" ixz="0.0" iyy="0.0007041666666666666" iyz="0.0" izz="6.666666666666667e-06"/>
    </inertial>
  </link>
  <joint name="pillar_fr_joint" type="fixed">
    <parent link="chassis"/>
    <child link="pillar_fr"/>
    <origin xyz="0.24 -0.23 0.145"/>
  </joint>
  <link name="pillar_fr">
    <visual>
      <geometry>
        <box size="0.02 0.02 0.29"/>
      </geometry>
      <material name="black"/>
    </visual>
    <collision>
      <geometry>
        <box size="0.02 0.02 0.29"/>
      </geometry>
    </collision>
    <inertial>
      <origin rpy="0 0 0" xyz="0 0 0"/>
      <mass value="0.1"/>
      <inertia ixx="0.0007041666666666666" ixy="0.0" ixz="0.0" iyy="0.0007041666666666666" iyz="0.0" izz="6.666666666666667e-06"/>
    </inertial>
  </link>
  <joint name="pillar_rl_joint" type="fixed">
    <parent link="chassis"/>
    <child link="pillar_rl"/>
    <origin xyz="-0.24 0.23 0.145"/>
  </joint>
  <link name="pillar_rl">
    <visual>
      <geometry>
        <box size="0.02 0.02 0.29"/>
      </geometry>
      <material name="black"/>
    </visual>
    <collision>
      <geometry>
        <box size="0.02 0.02 0.29"/>
      </geometry>
    </collision>
    <inertial>
      <origin rpy="0 0 0" xyz="0 0 0"/>
      <mass value="0.1"/>
      <inertia ixx="0.0007041666666666666" ixy="0.0" ixz="0.0" iyy="0.0007041666666666666" iyz="0.0" izz="6.666666666666667e-06"/>
    </inertial>
  </link>
  <joint name="pillar_rr_joint" type="fixed">
    <parent link="chassis"/>
    <child link="pillar_rr"/>
    <origin xyz="-0.24 -0.23 0.145"/>
  </joint>
  <link name="pillar_rr">
    <visual>
      <geometry>
        <box size="0.02 0.02 0.29"/>
      </geometry>
      <material name="black"/>
    </visual>
    <collision>
      <geometry>
        <box size="0.02 0.02 0.29"/>
      </geometry>
    </collision>
    <inertial>
      <origin rpy="0 0 0" xyz="0 0 0"/>
      <mass value="0.1"/>
      <inertia ixx="0.0007041666666666666" ixy="0.0" ixz="0.0" iyy="0.0007041666666666666" iyz="0.0" izz="6.666666666666667e-06"/>
    </inertial>
  </link>
  <joint name="plate_top_cover_joint" type="fixed">
    <parent link="chassis"/>
    <child link="plate_top_cover"/>
    <origin xyz="0 0 1.03"/>
  </joint>
  <link name="plate_top_cover">
    <visual>
      <geometry>
        <box size="0.25 0.28 0.01"/>
      </geometry>
      <material name="white"/>
    </visual>
    <collision>
      <geometry>
        <box size="0.255 0.285 0.01"/>
      </geometry>
    </collision>
    <inertial>
      <origin rpy="0 0 0" xyz="0 0 0"/>
      <mass value="0.2"/>
      <inertia ixx="0.0013554166666666667" ixy="0.0" ixz="0.0" iyy="0.0010854166666666666" iyz="0.0" izz="0.0024375"/>
    </inertial>
  </link>
  <joint name="plate_bottom_joint" type="fixed">
    <parent link="chassis"/>
    <child link="plate_bottom"/>
    <origin xyz="0 0 0.005"/>
  </joint>
  <link name="plate_bottom">
    <visual>
      <geometry>
        <box size="0.5 0.5 0.01"/>
      </geometry>
      <material name="red"/>
    </visual>
    <collision>
      <geometry>
        <box size="0.5 0.5 0.01"/>
      </geometry>
    </collision>
    <inertial>
      <origin rpy="0 0 0" xyz="0 0 0"/>
      <mass value="0.2"/>
      <inertia ixx="0.004168333333333333" ixy="0.0" ixz="0.0" iyy="0.004168333333333333" iyz="0.0" izz="0.008333333333333333"/>
    </inertial>
  </link>
  <joint name="plate_middle_joint" type="fixed">
    <parent link="chassis"/>
    <child link="plate_middle"/>
    <origin xyz="0 0 0.125"/>
  </joint>
  <link name="plate_middle">
    <visual>
      <geometry>
        <box size="0.5 0.5 0.01"/>
      </geometry>
      <material name="red"/>
    </visual>
    <collision>
      <geometry>
        <box size="0.5 0.5 0.01"/>
      </geometry>
    </collision>
    <inertial>
      <origin rpy="0 0 0" xyz="0 0 0"/>
      <mass value="0.2"/>
      <inertia ixx="0.004168333333333333" ixy="0.0" ixz="0.0" iyy="0.004168333333333333" iyz="0.0" izz="0.008333333333333333"/>
    </inertial>
  </link>
  <joint name="plate_top_joint" type="fixed">
    <parent link="chassis"/>
    <child link="plate_top"/>
    <origin xyz="0 0 0.285"/>
  </joint>
  <link name="plate_top">
    <visual>
      <geometry>
        <box size="0.5 0.5 0.01"/>
      </geometry>
      <material name="red"/>
    </visual>
    <collision>
      <geometry>
        <box size="0.5 0.5 0.01"/>
      </geometry>
    </collision>
    <inertial>
      <origin rpy="0 0 0" xyz="0 0 0"/>
      <mass value="0.2"/>
      <inertia ixx="0.004168333333333333" ixy="0.0" ixz="0.0" iyy="0.004168333333333333" iyz="0.0" izz="0.008333333333333333"/>
    </inertial>
  </link>
  <!-- Gazeboo -->
  <joint name="rear_left_wheel_joint" type="continuous">
    <parent link="base_link"/>
    <child link="rear_left_wheel"/>
    <origin rpy="-1.5707963267948966 0 0" xyz="-0.13 0.135 -0.015"/>
    <axis xyz="0 0 1"/>
  </joint>
  <link name="rear_left_wheel">
    <visual>
      <geometry>
        <cylinder length="0.03" radius="0.055"/>
      </geometry>
      <material name="blue"/>
    </visual>
    <collision>
      <geometry>
        <cylinder length="0.03" radius="0.055"/>
      </geometry>
    </collision>
    <inertial>
      <origin rpy="0 0 0" xyz="0 0 0"/>
      <mass value="1.5"/>
      <inertia ixx="0.001246875" ixy="0.0" ixz="0.0" iyy="0.001246875" iyz="0.0" izz="0.00226875"/>
    </inertial>
  </link>
  <joint name="rear_right_wheel_joint" type="continuous">
    <parent link="base_link"/>
    <child link="rear_right_wheel"/>
    <origin rpy="1.5707963267948966 0 0" xyz="-0.13 -0.135 -0.015"/>
    <axis xyz="0 0 -1"/>
  </joint>
  <link name="rear_right_wheel">
    <visual>
      <geometry>
        <cylinder length="0.03" radius="0.055"/>
      </geometry>
      <material name="blue"/>
    </visual>
    <collision>
      <geometry>
        <cylinder length="0.03" radius="0.055"/>
      </geometry>
    </collision>
    <inertial>
      <origin rpy="0 0 0" xyz="0 0 0"/>
      <mass value="1.5"/>
      <inertia ixx="0.001246875" ixy="0.0" ixz="0.0" iyy="0.001246875" iyz="0.0" izz="0.00226875"/>
    </inertial>
  </link>
  <joint name="front_left_wheel_joint" type="continuous">
    <parent link="base_link"/>
    <child link="front_left_wheel"/>
    <origin rpy="-1.5707963267948966 0 0" xyz="0.13 0.135 -0.015"/>
    <axis xyz="0 0 1"/>
  </joint>
  <link name="front_left_wheel">
    <visual>
      <geometry>
        <cylinder length="0.03" radius="0.055"/>
      </geometry>
      <material name="blue"/>
    </visual>
    <collision>
      <geometry>
        <cylinder length="0.03" radius="0.055"/>
      </geometry>
    </collision>
    <inertial>
      <origin rpy="0 0 0" xyz="0 0 0"/>
      <mass value="1.5"/>
      <inertia ixx="0.001246875" ixy="0.0" ixz="0.0" iyy="0.001246875" iyz="0.0" izz="0.00226875"/>
    </inertial>
  </link>
  <joint name="front_right_wheel_joint" type="continuous">
    <parent link="base_link"/>
    <child link="front_right_wheel"/>
    <origin rpy="1.5707963267948966 0 0" xyz="0.13 -0.135 -0.015"/>
    <axis xyz="0 0 -1"/>
  </joint>
  <link name="front_right_wheel">
    <visual>
      <geometry>
        <cylinder length="0.03" radius="0.055"/>
      </geometry>
      <material name="blue"/>
    </visual>
    <collision>
      <geometry>
        <cylinder length="0.03" radius="0.055"/>
      </geometry>
    </collision>
    <inertial>
      <origin rpy="0 0 0" xyz="0 0 0"/>
      <mass value="1.5"/>
      <inertia ixx="0.001246875" ixy="0.0" ixz="0.0" iyy="0.001246875" iyz="0.0" izz="0.00226875"/>
    </inertial>
  </link>
  <!-- Gazebo Material Assignments -->
  <!-- Plates -->
  <gazebo reference="plate_bottom">
    <material>Gazebo/Red</material>
  </gazebo>
  <gazebo reference="plate_middle">
    <material>Gazebo/Red</material>
  </gazebo>
  <gazebo reference="plate_top">
    <material>Gazebo/Red</material>
  </gazebo>
  <gazebo reference="plate_top_cover">
    <material>Gazebo/White</material>
  </gazebo>
  <!-- Pillars -->
  <gazebo reference="pillar_fl">
    <material>Gazebo/Black</material>
  </gazebo>
  <gazebo reference="pillar_fr">
    <material>Gazebo/Black</material>
  </gazebo>
  <gazebo reference="pillar_rl">
    <material>Gazebo/Black</material>
  </gazebo>
  <gazebo reference="pillar_rr">
    <material>Gazebo/Black</material>
  </gazebo>
  <gazebo reference="top_pillar_fl">
    <material>Gazebo/White</material>
  </gazebo>
  <gazebo reference="top_pillar_fr">
    <material>Gazebo/White</material>
  </gazebo>
  <gazebo reference="top_pillar_rl">
    <material>Gazebo/White</material>
  </gazebo>
  <gazebo reference="top_pillar_rr">
    <material>Gazebo/White</material>
  </gazebo>
  <!-- Chassis -->
  <gazebo reference="chassis">
    <material>Gazebo/White</material>
  </gazebo>
  <!-- Wheels -->
  <gazebo reference="rear_left_wheel">
    <material>Gazebo/Blue</material>
  </gazebo>
  <gazebo reference="rear_right_wheel">
    <material>Gazebo/Blue</material>
  </gazebo>
  <gazebo reference="front_left_wheel">
    <material>Gazebo/Blue</material>
    <mu1 value="0.001"/>
    <mu2 value="0.001"/>
  </gazebo>
  <gazebo reference="front_right_wheel">
    <material>Gazebo/Blue</material>
    <mu1 value="0.001"/>
    <mu2 value="0.001"/>
  </gazebo>
  <!-- Base Footprint Frame -->
  <joint name="base_footprint_joint" type="fixed">
    <parent link="base_link"/>
    <child link="base_footprint"/>
    <origin rpy="0 0 0" xyz="0 0 0"/>
  </joint>
  <link name="base_footprint"/>
  <ros2_control name="RealRobot" type="system">
    <hardware>
      <plugin>diffdrive_arduino/DiffDriveArduino</plugin>
      <param name="left_wheel_name">left_wheel_joint</param>
      <param name="right_wheel_name">right_wheel_joint</param>
      <param name="loop_rate">30</param>
      <param name="device">/dev/ttyUSB0</param>
      <param name="baud_rate">57600</param>
      <param name="timeout">1000</param>
      <param name="enc_counts_per_rev">3436</param>
    </hardware>
    <joint name="left_wheel_joint">
      <command_interface name="velocity">
        <param name="min">-10</param>
        <param name="max">10</param>
      </command_interface>
      <state_interface name="velocity"/>
      <state_interface name="position"/>
    </joint>
    <joint name="right_wheel_joint">
      <command_interface name="velocity">
        <param name="min">-10</param>
        <param name="max">10</param>
      </command_interface>
      <state_interface name="velocity"/>
      <state_interface name="position"/>
    </joint>
  </ros2_control>
  <gazebo>
    <plugin filename="libgazebo_ros2_control.so" name="gazebo_ros2_control">
      <parameters>/home/abcs/robo_ws/install/articubot_one/share/articubot_one/config/my_controllers.yaml</parameters>
      <parameters>/home/abcs/robo_ws/install/articubot_one/share/articubot_one/config/gaz_ros2_ctl_use_sim.yaml</parameters>
    </plugin>
  </gazebo>
  <joint name="laser_joint" type="fixed">
    <parent link="chassis"/>
    <child link="laser_frame"/>
    <origin rpy="0 0 0" xyz="0 0 0.1575"/>
  </joint>
  <link name="laser_frame">
    <visual>
      <geometry>
        <cylinder length="0.04" radius="0.05"/>
      </geometry>
      <material name="white"/>
    </visual>
    <collision>
      <geometry>
        <cylinder length="0.04" radius="0.05"/>
      </geometry>
    </collision>
    <inertial>
      <origin rpy="0 0 0" xyz="0 0 0"/>
      <mass value="0.1"/>
      <inertia ixx="7.583333333333335e-05" ixy="0.0" ixz="0.0" iyy="7.583333333333335e-05" iyz="0.0" izz="0.00012500000000000003"/>
    </inertial>
  </link>
  <gazebo reference="laser_frame">
    <material>Gazebo/white</material>
    <sensor name="laser" type="ray">
      <pose> 0 0 0 0 0 0 </pose>
      <visualize>false</visualize>
      <update_rate>10</update_rate>
      <ray>
        <scan>
          <horizontal>
            <samples>360</samples>
            <min_angle>-3.14</min_angle>
            <max_angle>3.14</max_angle>
          </horizontal>
        </scan>
        <range>
          <min>0.3475</min>
          <max>12</max>
        </range>
      </ray>
      <plugin filename="libgazebo_ros_ray_sensor.so" name="laser_controller">
        <ros>
          <argument>~/out:=scan</argument>
        </ros>
        <output_type>sensor_msgs/LaserScan</output_type>
        <frame_name>laser_frame</frame_name>
      </plugin>
    </sensor>
  </gazebo>
  <!-- <xacro:include filename="camera.xacro" /> -->
  <!-- <xacro:include filename="depth_camera.xacro" /> -->
  <!-- <xacro:include filename="face.xacro" /> -->
</robot>
